Workbook

Sheet 🏠 BERANDA
B1: 🍰 BUKU KEUANGAN USAHA CATERING & KUE
B4: ✨ Catat Pesanan · Hitung Untung · Kelola Keuangan dengan Mudah ✨
B6: 🏪 Nama Usaha : | D6: Catering & Kue Bu Sari
B7: 👩 Nama Pemilik : | D7: Bu Sari
B8: 📅 Tahun : | D8: 2025
B10: 📋 CARA PAKAI — CUKUP ISI DI SINI!
B11: 1️⃣ | C11: CATAT PESANAN | D11: Buka sheet '📦 Pesanan' → isi nama pemesan, menu, harga. Otomatis terhitung!
B12: 2️⃣ | C12: CATAT BELANJA | D12: Buka sheet '🛒 Belanja Bahan' → tulis semua bahan yang dibeli hari ini
B13: 3️⃣ | C13: CATAT BIAYA | D13: Buka sheet '💸 Biaya Lain' → gas, listrik, plastik kemasan, dll
B14: 4️⃣ | C14: CEK UNTUNG | D14: Buka sheet '💰 Laporan' → otomatis keluar berapa untung bulan ini!
B15: 5️⃣ | C15: LIHAT GRAFIK | D15: Buka sheet '📊 Grafik' → lihat perkembangan usaha dalam bentuk gambar
B18: 💡 RINGKASAN KEUANGAN — OTOMATIS TERHITUNG!
B19: KETERANGAN | D19: JUMLAH (Rp)
B20: 💰 TOTAL UANG MASUK (Pesanan) | D20: ='📦 Pesanan'!G3 -> 0
B21: 🛒 TOTAL BELANJA BAHAN | D21: ='🛒 Belanja Bahan'!E3 -> 2377000
B22: 💸 TOTAL BIAYA LAIN-LAIN | D22: ='💸 Biaya Lain'!D3 -> 425000
B23: 📦 TOTAL BIAYA (Bahan + Biaya) | D23: =D21+D22 -> 2802000
B24: 🎉 KEUNTUNGAN BERSIH | D24: =D20-D23 -> -2802000

Sheet 📦 Pesanan
B1: 📦 CATATAN PESANAN & UANG MASUK
B2: 💡 Isi kolom kuning. Kolom lain sudah otomatis terhitung. Jangan ubah kolom berwarna selain kuning!
B3: 📊 TOTAL UANG MASUK BULAN INI: | D3: =SUM(H8:H348) -> 5725000
B6: 🟡 Kolom Kuning = Isi sendiri | ⬜ Kolom Putih/Hijau = Otomatis | ✅ Status: LUNAS / BELUM BAYAR
B7: NO | C7: TANGGAL | D7: NAMA PEMESAN | E7: NAMA MENU / PESANAN | F7: JUMLAH (porsi/pcs) | G7: HARGA SATUAN (Rp) | H7: TOTAL (Rp) | I7: CATATAN
B8: 1 | C8: 45662 | D8: Bu Rina | E8: Nasi Box Ayam Bakar | F8: 50 | G8: 28000 | H8: =IF(G8*F8>0,G8*F8,"") -> 1400000
B9: 2 | C9: 45663 | D9: Pak Dodi | E9: Tumpeng Mini | F9: 1 | G9: 350000 | H9: =IF(G9*F9>0,G9*F9,"") -> 350000
B10: 3 | C10: 45664 | D10: Bu Hesti | E10: Kue Ulang Tahun | F10: 2 | G10: 180000 | H10: =IF(G10*F10>0,G10*F10,"") -> 360000
B11: 4 | C11: 45665 | D11: Bu Dewi | E11: Snack Box Arisan | F11: 30 | G11: 15000 | H11: =IF(G11*F11>0,G11*F11,"") -> 450000
B12: 5 | C12: 45666 | D12: Bu Lestari | E12: Nasi Kotak Catering | F12: 100 | G12: 25000 | H12: =IF(G12*F12>0,G12*F12,"") -> 2500000
B13: 6 | C13: 45667 | D13: Pak Agus | E13: Kue Kering Lebaran | F13: 5 | G13: 85000 | H13: =IF(G13*F13>0,G13*F13,"") -> 425000
B14: 7 | C14: 45668 | D14: Bu Yanti | E14: Puding Cokelat | F14: 20 | G14: 12000 | H14: =IF(G14*F14>0,G14*F14,"") -> 240000
B15: 8 | H15: =IF(G15*F15>0,G15*F15,"")
B16: 9 | H16: =IF(G16*F16>0,G16*F16,"")
B17: 10 | H17: =IF(G17*F17>0,G17*F17,"")
B18: 11 | H18: =IF(G18*F18>0,G18*F18,"")
B19: 12 | H19: =IF(G19*F19>0,G19*F19,"")
B20: 13 | H20: =IF(G20*F20>0,G20*F20,"")
B21: 14 | H21: =IF(G21*F21>0,G21*F21,"")
B22: 15 | H22: =IF(G22*F22>0,G22*F22,"")
B23: 16 | H23: =IF(G23*F23>0,G23*F23,"")
B24: 17 | H24: =IF(G24*F24>0,G24*F24,"")
B25: 18 | H25: =IF(G25*F25>0,G25*F25,"")
B26: 19 | H26: =IF(G26*F26>0,G26*F26,"")
... B49: 42 | H49: =IF(G49*F49>0,G49*F49,"")
B50: =B49+1 -> 43 | H50: =IF(G50*F50>0,G50*F50,"")
B51: =B50+1 -> 44 | H51: =IF(G51*F51>0,G51*F51,"")
B52: =B51+1 -> 45 | H52: =IF(G52*F52>0,G52*F52,"")
B53: =B52+1 -> 46 | H53: =IF(G53*F53>0,G53*F53,"")
B54: =B53+1 -> 47 | H54: =IF(G54*F54>0,G54*F54,"")
B55: =B54+1 -> 48 | H55: =IF(G55*F55>0,G55*F55,"")
B56: =B55+1 -> 49 | H56: =IF(G56*F56>0,G56*F56,"")
B57: =B56+1 -> 50 | H57: =IF(G57*F57>0,G57*F57,"")
B58: =B57+1 -> 51 | H58: =IF(G58*F58>0,G58*F58,"")
B59: =B58+1 -> 52 | H59: =IF(G59*F59>0,G59*F59,"")
B60: =B59+1 -> 53 | H60: =IF(G60*F60>0,G60*F60,"")
B61: =B60+1 -> 54 | H61: =IF(G61*F61>0,G61*F61,"")
... B348: =B347+1 -> 341 | H348: =IF(G348*F348>0,G348*F348,"")

Sheet 🛒 Belanja Bahan
B1: 🛒 CATATAN BELANJA BAHAN BAKU
B2: 💡 Catat semua belanja bahan di sini: tepung, gula, ayam, bumbu, dll
B3: 🛒 TOTAL BELANJA BAHAN BULAN INI: | E3: =SUM(I8:I198) -> 2377000
B5: 📌 Tips: Catat belanja setiap hari agar terlihat berapa besar biaya bahan per bulan
B7: NO | C7: TANGGAL | D7: NAMA BAHAN / BARANG | E7: TOKO / TEMPAT BELI | F7: VOLUME | G7: JUMLAH (kg/pcs/ltr) | H7: HARGA BELI | I7: JUMLAH | J7: CATATAN
B8: 1 | C8: 45662 | D8: Tepung Terigu | E8: Toko Sumber Makmur | F8: Kg | G8: 5 | H8: 65000 | I8: =G8*H8 -> 325000
B9: 2 | C9: 45663 | D9: Gula Pasir | E9: Toko Sumber Makmur | F9: Kg | G9: 3 | H9: 45000 | I9: =G9*H9 -> 135000
B10: 3 | C10: 45664 | D10: Mentega | E10: Toko Sumber Makmur | F10: Kg | G10: 2 | H10: 56000 | I10: =G10*H10 -> 112000
B11: 4 | C11: 45665 | D11: Ayam Kampung | E11: Pasar Terdekat | F11: Kg | G11: 3 | H11: 120000 | I11: =G11*H11 -> 360000
B12: 5 | C12: 45666 | D12: Telur Ayam | E12: Pasar Terdekat | F12: Kg | G12: 2 | H12: 38000 | I12: =G12*H12 -> 76000
B13: 6 | C13: 45667 | D13: Santan Kelapa | E13: Pasar Terdekat | F13: Ltr | G13: 1 | H13: 15000 | I13: =G13*H13 -> 15000
B14: 7 | C14: 45668 | D14: Bumbu Rendang | E14: Toko Bumbu Bu Yem | F14: Pcs | G14: 3 | H14: 18000 | I14: =G14*H14 -> 54000
B15: 10 | C15: 45669 | D15: Beras | E15: Toko Sumber Makmur | F15: Kg | G15: 10 | H15: 130000 | I15: =G15*H15 -> 1300000
B16: 11 | I16: =G16*H16 -> 0
B17: 12 | I17: =G17*H17 -> 0
B18: 13 | I18: =G18*H18 -> 0
B19: 14 | I19: =G19*H19 -> 0
B20: 15 | I20: =G20*H20 -> 0
B21: 16 | I21: =G21*H21 -> 0
B22: 17 | I22: =G22*H22 -> 0
B23: 18 | I23: =G23*H23 -> 0
B24: 19 | I24: =G24*H24 -> 0
B25: 20 | I25: =G25*H25 -> 0
B26: 21 | I26: =G26*H26 -> 0
B27: 22 | I27: =G27*H27 -> 0
... B390: 385 | I390: =G390*H390 -> 0

Sheet 💸 Biaya Lain
B1: 💸 BIAYA OPERASIONAL & LAIN-LAIN
B2: 💡 Gas, listrik, plastik kemasan, ongkir, dll — catat semua di sini
B3: 💸 TOTAL BIAYA LAIN BULAN INI: | D3: =SUM(F8:F200) -> 425000
B5: 📌 Contoh: Gas LPG, Listrik, Air, Plastik Kemasan, Kotak Kue, Label, Ongkos Kirim, dll
B7: NO | C7: TANGGAL | D7: KETERANGAN BIAYA | E7: KATEGORI | F7: JUMLAH (Rp) | G7: CATATAN
B8: 1 | C8: 45662 | D8: Gas LPG 12 kg | E8: Bahan Bakar | F8: 150000
B9: 2 | C9: 45663 | D9: Plastik Kemasan | E9: Kemasan | F9: 45000
B10: 3 | C10: 45664 | D10: Kotak Kue | E10: Kemasan | F10: 60000
B11: 4 | C11: 45665 | D11: Ongkos Kirim Pesanan | E11: Pengiriman | F11: 50000
B12: 5 | C12: 45666 | D12: Label Stiker | E12: Kemasan | F12: 25000
B13: 6 | C13: 45667 | D13: Listrik (perkiraan) | E13: Listrik & Air | F13: 80000
B14: 7 | C14: 45668 | D14: Tusuk Gigi & Sendok | E14: Perlengkapan | F14: 15000
B15: 8
B16: 9
B17: 10
B18: 11
B19: 12
B20: 13
B21: 14
B22: 15
B23: 16
B24: 17
B25: 18
B26: 19
... B50: 43

Sheet 💰 Laporan
B1: 💰 LAPORAN KEUANGAN BULANAN
B2: ✨ Semua angka otomatis dari data yang kamu isi — tidak perlu hitung manual!
B4: 💰 A. UANG MASUK (PENDAPATAN)
B5: ➤ Total Hasil Pesanan / Penjualan | D5: ='📦 Pesanan'!D3 -> 5725000
B6: ➤ Pendapatan Lain-lain (isi manual) | D6: 0
B7: 📌 TOTAL UANG MASUK | D7: =D5+D6 -> 5725000
B9: 🛒 B. BIAYA BAHAN BAKU
B10: ➤ Total Belanja Bahan | D10: ='🛒 Belanja Bahan'!E3 -> 2377000
B11: 📌 TOTAL BIAYA BAHAN | D11: =D10 -> 2377000
B13: 💸 C. BIAYA OPERASIONAL LAIN
B14: ➤ Total Biaya Lain-lain | D14: ='💸 Biaya Lain'!D3 -> 425000
B15: 📌 TOTAL BIAYA OPERASIONAL | D15: =D14 -> 425000
B17: 📊 D. PERHITUNGAN HPP
B18: ➤ Total Biaya Bahan Baku | D18: =D11 -> 2377000
B19: ➤ Total Biaya Operasional | D19: =D15 -> 425000
B20: 📌 TOTAL HPP (Harga Pokok Penjualan) | D20: =D18+D19 -> 2802000
B22: 🎉 E. KEUNTUNGAN
B23: ➤ Total Uang Masuk | D23: =D7 -> 5725000
B24: ➤ Total HPP | D24: =D20 -> 2802000
B25: 🎊 KEUNTUNGAN BERSIH | D25: =D23-D24 -> 2923000
B27: 📈 MARGIN KEUNTUNGAN (%) | D27: =IF(D7>0,D25/D7,0) -> 0.51056769
B28: (Idealnya minimal 30% dari total penjualan)
B31: 💡 ANALISIS & SARAN OTOMATIS
B32: =IF(D25>0,"✅ Alhamdulillah! Bulan ini UNTUNG Rp "&TEXT(D25,"#,##0")&" — Lanjutkan terus!",IF(D25=0,"⚠️ Impas — Coba naikkan harga atau kurangi biaya bahan","🔴 Bulan ini RUGI "&TEXT(ABS(D25),"#,##0")&" — Cek biaya yang terlalu besar")) -> ✅ Alhamdulillah! Bulan ini UNTUNG Rp 2923000,0 — Lanjutkan terus!

Sheet 🍱 HPP Per Menu
B1: 🍱 HITUNG HARGA POKOK PER MENU
B2: 💡 Bantu kamu tahu berapa harga MINIMAL jual agar tidak rugi!
B4: 🍽️ AYAM BAKAR (1 porsi)
B5: BAHAN | C5: QTY | D5: SATUAN | E5: HARGA SATUAN | F5: HARGA SATUAN
B6: Ayam | C6: 2 | D6: Kg | E6: 40000 | F6: =C6*E6 -> 80000
B7: Bawang Putih | C7: 200 | D7: gr | E7: 11000 | F7: 11000
B8: Ketumbar Bubuk | C8: 1 | D8: pcs | E8: 3000 | F8: =C8*E8 -> 3000
B9: Kaldu Bubuk | C9: 2 | D9: pcs | E9: 3000 | F9: =C9*E9 -> 6000
B10: Air | C10: 2 | D10: Liter | E10: 2000 | F10: =C10*E10 -> 4000
B11: Minyak Goreng | C11: 500 | D11: ml | E11: 8000 | F11: 8000
B12: Gas | C12: 1 | D12: Kali | E12: 15000 | F12: =C12*E12 -> 15000
B13: Packaging | C13: 10 | D13: pcs | E13: 2000 | F13: =C13*E13 -> 20000
B14: 📌 TOTAL HPP (Harga Pokok Produksi) | F14: =SUM(F6:F13) -> 147000
B15: Jumlah Produksi | F15: 10
B16: Harga Jual Sekarang | F16: 18000
B17: Laba Kotor | F17: =F16*F15 -> 180000
B18: Laba Berssih | F18: =F17-F14 -> 33000
B20: 🍽️ KUE ULANG TAHUN (1 loyang)
B21: BAHAN | C21: SATUAN | D21: QTY | E21: TOTAL
B22: Tepung Terigu | C22: gr | D22: 250 | E22: 3000
B23: Gula Pasir | C23: gr | D23: 200 | E23: 2800
B24: Mentega | C24: gr | D24: 150 | E24: 4500
B25: Telur | C25: butir | D25: 4 | E25: 8000
B26: Cokelat Bubuk | C26: gr | D26: 50 | E26: 5000
B27: Keju Parut | C27: gr | D27: 100 | E27: 9000
B28: Kotak Kue | C28: pcs | D28: 1 | E28: 5000
B29: 📌 TOTAL HPP (Harga Pokok Per Porsi) | E29: =SUM(E22:F28) -> 37300
B30: 💰 Harga Jual Sekarang | E30: 50000
B31: 🎉 Untung Per Porsi | E31: =E30-E29 -> 12700

Sheet 📊 Grafik
A1: 📊 GRAFIK KEUANGAN USAHA
A2: Otomatis dari data pesanan & pengeluaran
A4: KETERANGAN | B4: JUMLAH (Rp)
A5: Uang Masuk | B5: ='📦 Pesanan'!D3 -> 5725000
A6: Biaya Bahan | B6: ='🛒 Belanja Bahan'!E3 -> 2377000
A7: Biaya Lain | B7: ='💸 Biaya Lain'!D3 -> 425000
A8: Keuntungan | B8: ='💰 Laporan'!D25 -> 2923000
A50: BULAN | B50: UANG MASUK | C50: TOTAL BIAYA | D50: KEUNTUNGAN
A51: Januari | B51: 0 | C51: 0 | D51: 0
A52: Februari | B52: 0 | C52: 0 | D52: 0
A53: Maret | B53: 0 | C53: 0 | D53: 0
A54: April | B54: 0 | C54: 0 | D54: 0
A55: Mei | B55: 0 | C55: 0 | D55: 0
A56: Juni | B56: 0 | C56: 0 | D56: 0
A57: Juli | B57: 0 | C57: 0 | D57: 0
A58: Agustus | B58: 0 | C58: 0 | D58: 0
A59: September | B59: 0 | C59: 0 | D59: 0
A60: Oktober | B60: 0 | C60: 0 | D60: 0
A61: November | B61: 0 | C61: 0 | D61: 0
A62: Desember | B62: 0 | C62: 0 | D62: 0

Sheet 📒 Jurnal Umum
B1: 📒 JURNAL UMUM — CATERING & KUE
B2: 💡 Jurnal Umum mencatat SETIAP transaksi keuangan usaha: uang masuk, belanja, bayar listrik, dll
B4: 🏪 Nama Usaha: | E4: Catering & Kue Bu Sari
B5: 📅 Periode: | E5: Januari 2025
B7: 🟢 Uang Masuk (Debit Kas) | 🔴 Belanja/Bayar (Kredit Kas) | 🟡 Kolom Kuning = Isi Sendiri | ✅ Balance = Debit = Kredit
B8: NO. | C8: TANGGAL | D8: AKUN / KETERANGAN | E8: NAMA TRANSAKSI (Apa yang Terjadi) | F8: REF (Kode) | G8: DEBIT | H8: KREDIT
B9: 1 | C9: 2025-01-05 | D9: KAS (Uang Tunai Masuk) | E9: Terima bayaran pesanan nasi box ayam bakar 50 porsi - Bu Rina | F9: 4010 | G9: 1400000
B10: 1 | D10: PENDAPATAN PENJUALAN | E10: Terima bayaran pesanan nasi box ayam bakar 50 porsi - Bu Rina | F10: 4010 | H10: 1400000
B11: 2 | C11: 2025-01-08 | D11: KAS (Uang Tunai Masuk) | E11: Terima DP pesanan tumpeng mini - Pak Dodi | F11: 4010 | G11: 350000
B12: 2 | D12: PENDAPATAN PENJUALAN | E12: Terima DP pesanan tumpeng mini - Pak Dodi | F12: 4010 | H12: 350000
B13: 3 | C13: 2025-01-03 | D13: BIAYA BAHAN BAKU | E13: Belanja tepung, gula, mentega di Toko Sumber Makmur | F13: 5010 | G13: 166000
B14: 3 | D14: KAS (Uang Tunai Keluar) | E14: Belanja tepung, gula, mentega di Toko Sumber Makmur | F14: 5010 | H14: 166000
B15: 4 | C15: 2025-01-05 | D15: BIAYA BAHAN BAKU | E15: Belanja ayam kampung 3 kg di Pasar | F15: 5010 | G15: 120000
B16: 4 | D16: KAS (Uang Tunai Keluar) | E16: Belanja ayam kampung 3 kg di Pasar | F16: 5010 | H16: 120000
B17: 5 | C17: 2025-01-01 | D17: BIAYA GAS & LISTRIK | E17: Beli gas LPG 12 kg | F17: 6010 | G17: 150000
B18: 5 | D18: KAS (Uang Tunai Keluar) | E18: Beli gas LPG 12 kg | F18: 6010 | H18: 150000
B19: 6 | C19: 2025-01-01 | D19: BIAYA KEMASAN | E19: Beli plastik & kotak kue | F19: 6020 | G19: 105000
B20: 6 | D20: KAS (Uang Tunai Keluar) | E20: Beli plastik & kotak kue | F20: 6020 | H20: 105000
B21: 7 | C21: 2025-01-10 | D21: KAS (Uang Tunai Masuk) | E21: Terima bayaran pesanan kue ulang tahun 2 loyang - Bu Hesti | F21: 4010 | G21: 360000
B22: 7 | D22: PENDAPATAN PENJUALAN | E22: Terima bayaran pesanan kue ulang tahun 2 loyang - Bu Hesti | F22: 4010 | H22: 360000
B23: 8 | C23: 2025-01-12 | D23: KAS (Uang Tunai Masuk) | E23: Terima bayaran snack box arisan 30 pcs - Bu Dewi | F23: 4010 | G23: 450000
B24: 8 | D24: PENDAPATAN PENJUALAN | E24: Terima bayaran snack box arisan 30 pcs - Bu Dewi | F24: 4010 | H24: 450000
B25: 9 | C25: 2025-01-10 | D25: BIAYA BAHAN BAKU | E25: Belanja telur, santan, bumbu rendang | F25: 5010 | G25: 71000
B26: 9 | D26: KAS (Uang Tunai Keluar) | E26: Belanja telur, santan, bumbu rendang | F26: 5010 | H26: 71000
B27: 10 | C27: 2025-01-12 | D27: BIAYA PENGIRIMAN | E27: Ongkos kirim pesanan snack box Bu Dewi | F27: 6030 | G27: 50000
B28: 10 | D28: KAS (Uang Tunai Keluar) | E28: Ongkos kirim pesanan snack box Bu Dewi | F28: 6030 | H28: 50000
B29: 11 | C29: 2025-01-15 | D29: KAS (Uang Tunai Masuk) | E29: Terima bayaran catering nasi kotak 100 porsi - Bu Lestari | F29: 4010 | G29: 2500000
B30: 11 | D30: PENDAPATAN PENJUALAN | E30: Terima bayaran catering nasi kotak 100 porsi - Bu Lestari | F30: 4010 | H30: 2500000
B31: 12 | C31: 2025-01-13 | D31: BIAYA BAHAN BAKU | E31: Belanja bahan untuk katering 100 porsi: beras, ayam, bumbu | F31: 5010 | G31: 800000
B32: 12 | D32: KAS (Uang Tunai Keluar) | E32: Belanja bahan untuk katering 100 porsi: beras, ayam, bumbu | F32: 5010 | H32: 800000
B33: 13 | C33: 2025-01-20 | D33: BIAYA PERLENGKAPAN | E33: Beli label stiker & tusuk gigi | F33: 6040 | G33: 40000
B34: 13 | D34: KAS (Uang Tunai Keluar) | E34: Beli label stiker & tusuk gigi | F34: 6040 | H34: 40000
B35: 14 | C35: 2025-01-20 | D35: BIAYA LISTRIK | E35: Bayar listrik bulan Januari | F35: 6010 | G35: 80000
B36: 14 | D36: KAS (Uang Tunai Keluar) | E36: Bayar listrik bulan Januari | F36: 6010 | H36: 80000
B37: 15 | C37: 2025-01-18 | D37: PIUTANG USAHA | E37: Pesanan kue kering Pak Agus 5 toples (belum bayar) | F37: 4010 | G37: 425000
B38: 15 | D38: PENDAPATAN PENJUALAN | E38: Pesanan kue kering Pak Agus 5 toples (belum bayar) | F38: 4010 | H38: 425000
B59: 📊 TOTAL JURNAL UMUM | G59: =SUM(G9:G58) -> 7067000 | H59: =SUM(H9:H58) -> 7067000
B61: 💡 CARA BACA JURNAL: Setiap transaksi selalu punya 2 baris. Baris 1 = DEBIT (uang/nilai masuk ke akun). Baris 2 = KREDIT (uang/nilai keluar dari akun). Total Debit HARUS selalu sama dengan Total Kredit. ✅

Sheet 📋 Laporan Keuangan
B1: 📋 LAPORAN KEUANGAN LENGKAP
B2: Laporan Laba Rugi · Laporan Perubahan Modal · Neraca | Semua otomatis dari data pesanan & pengeluaran
B4: 🏪 Nama Usaha: | D4: Catering & Kue Bu Sari
B5: 📅 Periode Laporan: | D5: Bulan Januari 2025
B6: 👩 Pemilik: | D6: Bu Sari
B8: 📊 LAPORAN LABA RUGI
B9: A. PENDAPATAN USAHA
B10: Pendapatan dari Penjualan Catering & Kue | D10: ='📦 Pesanan'!D3 -> 5725000
B11: Pendapatan Lain-lain (isi manual jika ada) | D11: 0
B12: TOTAL PENDAPATAN | D12: =D10+D11 -> 5725000
B14: B. HARGA POKOK PENJUALAN (HPP)
B15: Total Biaya Bahan Baku yang Dipakai | D15: ='🛒 Belanja Bahan'!E3 -> 2377000
B16: Total Biaya Operasional Produksi | D16: ='💸 Biaya Lain'!D3 -> 425000
B17: TOTAL HPP | D17: =D15+D16 -> 2802000
B19: LABA KOTOR (Pendapatan − HPP) | D19: =D12-D17 -> 2923000
B21: C. BEBAN OPERASIONAL
B22: Beban Pengiriman / Ongkir | D22: 50000
B23: Beban Perlengkapan (label, dll) | D23: 40000
B24: Beban Lain-lain (isi manual) | D24: 0
B25: TOTAL BEBAN OPERASIONAL | D25: =SUM(D22:D24) -> 90000
B27: LABA BERSIH SEBELUM PAJAK (Laba Kotor − Beban) | D27: =D19-D25 -> 2833000
B28: Pajak Penghasilan (PPh — isi jika kena pajak) | D28: 0
B29: 🎉 LABA BERSIH | D29: =D27-D28 -> 2833000
B31: 📈 Margin Keuntungan Bersih (%) | D31: =IF(D12>0,D29/D12,0) -> 0.49484716
B32: 📦 Rata-rata Keuntungan Per Hari (30 hari) | D32: =IF(D29>0,D29/30,0) -> 94433.333
B34: 💼 LAPORAN PERUBAHAN MODAL
B35: Modal Awal Usaha (di awal periode) | D35: 5665000
B36: Tambah: Laba Bersih Periode Ini | D36: =D29 -> 2833000
B37: Kurang: Prive / Uang diambil pemilik (isi manual) | D37: 0
B38: MODAL AKHIR | D38: =D35+D36-D37 -> 8498000
B40: ⚖️ NERACA (POSISI KEUANGAN)
B41: ASET (Harta Usaha)
B42: Kas / Uang Tunai yang Tersisa | D42: =D12-D17-D25 -> 2833000
B43: Piutang (Pelanggan Belum Bayar) | D43: ='💳 Hutang & Piutang'!E18 -> 665000
B44: Persediaan Bahan Baku (sisa bahan) | D44: 0
B45: Peralatan Dapur (oven, mixer, dll) | D45: 5000000
B46: TOTAL ASET | D46: =D42+D43+D44+D45 -> 8498000
B48: KEWAJIBAN (Hutang)
B49: Hutang ke Supplier / Toko (belum dibayar) | D49: 0
B50: Hutang Lain-lain (isi manual) | D50: 0
...

Sheet 📅 Rekap Bulanan
B1: 📅 REKAP KEUANGAN BULANAN — 2025
B2: 💡 Isi uang masuk, biaya bahan, dan biaya lain tiap bulan — keuntungan dihitung otomatis!
B4: BULAN | C4: UANG MASUK (Rp) | D4: BIAYA BAHAN (Rp) | E4: BIAYA LAIN (Rp) | F4: TOTAL BIAYA (Rp) | G4: KEUNTUNGAN (Rp) | H4: MARGIN (%) | I4: STATUS
B5: Januari | C5: ='📦 Pesanan'!D3 -> 5725000 | D5: ='🛒 Belanja Bahan'!E3 -> 2377000 | E5: ='💸 Biaya Lain'!D3 -> 425000 | F5: =D5+E5 -> 2802000 | G5: =C5-F5 -> 2923000 | H5: =IF(C5>0,G5/C5,0) -> 0.51056769 | I5: =IF(G5>0,"✅ UNTUNG",IF(G5=0,"⚖️ IMPAS","🔴 RUGI")) -> ✅ UNTUNG
B6: Februari | C6: 0 | D6: 0 | E6: 0 | F6: =D6+E6 -> 0 | G6: =C6-F6 -> 0 | H6: =IF(C6>0,G6/C6,0) -> 0 | I6: =IF(G6>0,"✅ UNTUNG",IF(G6=0,"⚖️ IMPAS","🔴 RUGI")) -> ⚖️ IMPAS
B7: Maret | C7: 0 | D7: 0 | E7: 0 | F7: =D7+E7 -> 0 | G7: =C7-F7 -> 0 | H7: =IF(C7>0,G7/C7,0) -> 0 | I7: =IF(G7>0,"✅ UNTUNG",IF(G7=0,"⚖️ IMPAS","🔴 RUGI")) -> ⚖️ IMPAS
B8: April | C8: 0 | D8: 0 | E8: 0 | F8: =D8+E8 -> 0 | G8: =C8-F8 -> 0 | H8: =IF(C8>0,G8/C8,0) -> 0 | I8: =IF(G8>0,"✅ UNTUNG",IF(G8=0,"⚖️ IMPAS","🔴 RUGI")) -> ⚖️ IMPAS
B9: Mei | C9: 0 | D9: 0 | E9: 0 | F9: =D9+E9 -> 0 | G9: =C9-F9 -> 0 | H9: =IF(C9>0,G9/C9,0) -> 0 | I9: =IF(G9>0,"✅ UNTUNG",IF(G9=0,"⚖️ IMPAS","🔴 RUGI")) -> ⚖️ IMPAS
B10: Juni | C10: 0 | D10: 0 | E10: 0 | F10: =D10+E10 -> 0 | G10: =C10-F10 -> 0 | H10: =IF(C10>0,G10/C10,0) -> 0 | I10: =IF(G10>0,"✅ UNTUNG",IF(G10=0,"⚖️ IMPAS","🔴 RUGI")) -> ⚖️ IMPAS
B11: Juli | C11: 0 | D11: 0 | E11: 0 | F11: =D11+E11 -> 0 | G11: =C11-F11 -> 0 | H11: =IF(C11>0,G11/C11,0) -> 0 | I11: =IF(G11>0,"✅ UNTUNG",IF(G11=0,"⚖️ IMPAS","🔴 RUGI")) -> ⚖️ IMPAS
B12: Agustus | C12: 0 | D12: 0 | E12: 0 | F12: =D12+E12 -> 0 | G12: =C12-F12 -> 0 | H12: =IF(C12>0,G12/C12,0) -> 0 | I12: =IF(G12>0,"✅ UNTUNG",IF(G12=0,"⚖️ IMPAS","🔴 RUGI")) -> ⚖️ IMPAS
B13: September | C13: 0 | D13: 0 | E13: 0 | F13: =D13+E13 -> 0 | G13: =C13-F13 -> 0 | H13: =IF(C13>0,G13/C13,0) -> 0 | I13: =IF(G13>0,"✅ UNTUNG",IF(G13=0,"⚖️ IMPAS","🔴 RUGI")) -> ⚖️ IMPAS
B14: Oktober | C14: 0 | D14: 0 | E14: 0 | F14: =D14+E14 -> 0 | G14: =C14-F14 -> 0 | H14: =IF(C14>0,G14/C14,0) -> 0 | I14: =IF(G14>0,"✅ UNTUNG",IF(G14=0,"⚖️ IMPAS","🔴 RUGI")) -> ⚖️ IMPAS
B15: November | C15: 0 | D15: 0 | E15: 0 | F15: =D15+E15 -> 0 | G15: =C15-F15 -> 0 | H15: =IF(C15>0,G15/C15,0) -> 0 | I15: =IF(G15>0,"✅ UNTUNG",IF(G15=0,"⚖️ IMPAS","🔴 RUGI")) -> ⚖️ IMPAS
B16: Desember | C16: 0 | D16: 0 | E16: 0 | F16: =D16+E16 -> 0 | G16: =C16-F16 -> 0 | H16: =IF(C16>0,G16/C16,0) -> 0 | I16: =IF(G16>0,"✅ UNTUNG",IF(G16=0,"⚖️ IMPAS","🔴 RUGI")) -> ⚖️ IMPAS
B17: 📊 TOTAL SETAHUN | C17: =SUM(C5:C16) -> 5725000 | D17: =SUM(D5:D16) -> 2377000 | E17: =SUM(E5:E16) -> 425000 | F17: =SUM(F5:F16) -> 2802000 | G17: =SUM(G5:G16) -> 2923000 | H17: =IF(C17>0,G17/C17,0) -> 0.51056769 | I17: =IF(G17>0,"✅ UNTUNG",IF(G17=0,"⚖️ IMPAS","🔴 RUGI")) -> ✅ UNTUNG
B19: 📈 GRAFIK TREN KEUNTUNGAN BULANAN

Sheet 💳 Hutang & Piutang
B1: 💳 CATATAN HUTANG & PIUTANG
B2: 💡 Hutang = kamu yang belum bayar ke orang | Piutang = orang yang belum bayar ke kamu
B4: 💰 PIUTANG — Pelanggan Yang Belum Bayar ke Kamu
B5: TANGGAL PESANAN | C5: NAMA PELANGGAN | D5: MENU / DESKRIPSI | E5: JUMLAH TAGIHAN (Rp) | F5: TANGGAL JATUH TEMPO | G5: STATUS | H5: CATATAN
B6: 2025-01-18 | C6: Pak Agus | D6: Kue Kering Lebaran 5 toples | E6: 425000 | F6: 2025-01-25 | G6: ⏳ BELUM BAYAR | H6: Sudah diingatkan 1x
B7: 2025-01-20 | C7: Bu Yanti | D7: Puding Cokelat 20 pcs | E7: 240000 | F7: 2025-01-27 | G7: ⏳ BELUM BAYAR
B18: 💰 TOTAL PIUTANG BELUM TERBAYAR | E18: =SUMIF(G6:G17,"*BELUM*",E6:E17) -> 665000
B20: 🛒 HUTANG — Yang Belum Kamu Bayar ke Toko / Supplier
B21: TANGGAL BELI | C21: NAMA TOKO/SUPPLIER | D21: KETERANGAN BELANJA | E21: JUMLAH HUTANG (Rp) | F21: TANGGAL JATUH TEMPO | G21: STATUS | H21: CATATAN
B34: 🛒 TOTAL HUTANG BELUM DIBAYAR | E34: =SUMIF(G22:G33,"*BELUM*",E22:E33) -> 0

Sheet Lembar1

Sheet 🍽️ Daftar Menu
B1: 🍽️ DAFTAR MENU & HARGA JUAL
B2: 💡 Isi daftar menu usahamu di sini — bisa dicetak dan dibagikan ke pelanggan!
B4: 🍱 KATEGORI: NASI BOX & CATERING
B5: NAMA MENU | C5: DESKRIPSI | D5: HARGA JUAL (Rp) | E5: MIN. PESAN (porsi) | F5: TERSEDIA? | G5: CATATAN/BAHAN | H5: WAKTU PERSIAPAN
B6: Nasi Box Ayam Bakar | C6: Nasi putih + ayam bakar + lalapan + sambal | D6: 28000 | E6: 20 | F6: ✅ Ada | G6: Pesan H-1 | H6: 1 hari
B7: Nasi Box Rendang | C7: Nasi putih + rendang sapi + sayur + kerupuk | D7: 35000 | E7: 20 | F7: ✅ Ada | G7: Pesan H-2 | H7: 2 hari
B8: Nasi Kotak Prasmanan | C8: Pilih 1 lauk dari menu tersedia | D8: 25000 | E8: 50 | F8: ✅ Ada | G8: Hubungi dulu | H8: 2 hari
B9: Tumpeng Mini | C9: Nasi kuning + lauk lengkap (porsi kecil) | D9: 350000 | E9: 1 | F9: ✅ Ada | G9: Pesan H-2 | H9: 2 hari
B10: Tumpeng Besar | C10: Nasi kuning + lauk lengkap (porsi keluarga) | D10: 650000 | E10: 1 | F10: ✅ Ada | G10: Pesan H-3 | H10: 3 hari
B11: Snack Box Arisan | C11: Gorengan + kue + minuman | D11: 15000 | E11: 30 | F11: ✅ Ada | G11: Pesan H-1 | H11: 1 hari
B13: 🎂 KATEGORI: KUE & DESSERT
B14: NAMA MENU | C14: DESKRIPSI | D14: HARGA JUAL (Rp) | E14: SATUAN | F14: TERSEDIA? | G14: CATATAN/BAHAN | H14: WAKTU PERSIAPAN
B15: Kue Ulang Tahun | C15: Kue lapis cokelat + keju, dekorasi custom | D15: 180000 | E15: 1 loyang | F15: ✅ Ada | G15: Pesan H-2 | H15: 2 hari
B16: Brownies Panggang | C16: Brownies cokelat tebal, bisa custom topping | D16: 65000 | E16: 1 loyang | F16: ✅ Ada | G16: Pesan H-1 | H16: 1 hari
B17: Puding Cokelat | C17: Puding susu + saus cokelat, cup plastik | D17: 12000 | E17: 1 cup | F17: ✅ Ada | G17: Pesan H-1 | H17: 1 hari
B18: Kue Kering Lebaran | C18: Nastar, putri salju, kastengel — 1 toples | D18: 85000 | E18: 1 toples | F18: ✅ Ada | G18: Musiman | H18: 3 hari
B19: Kue Basah Tradisional | C19: Klepon, onde-onde, lemper — per biji | D19: 3500 | E19: per biji | F19: ✅ Ada | G19: Pesan H-1 | H19: 1 hari
B20: Bolu Kukus Pelangi | C20: Bolu warna-warni untuk hantaran/kondangan | D20: 75000 | E20: 1 loyang | F20: ✅ Ada | G20: Pesan H-1 | H20: 1 hari
B21: Risoles Mayo | C21: Risoles isi sayur + mayo, digoreng crispy | D21: 4500 | E21: per biji | F21: ✅ Ada | G21: Pesan H-1 | H21: 1 hari
B23: 🥤 KATEGORI: MINUMAN
B24: NAMA MENU | C24: DESKRIPSI | D24: HARGA JUAL (Rp) | E24: SATUAN | F24: TERSEDIA? | G24: CATATAN/BAHAN | H24: WAKTU PERSIAPAN
B25: Es Teh Manis | C25: Teh manis dingin, gelas plastik + sedotan | D25: 5000 | E25: per gelas | F25: ✅ Ada | G25: Pesan H-1 | H25: 1 hari
B26: Es Jeruk | C26: Jeruk peras segar + gula + es | D26: 7000 | E26: per gelas | F26: ✅ Ada | G26: Pesan H-1 | H26: 1 hari
B27: Jus Alpukat | C27: Jus alpukat segar + susu kental manis | D27: 12000 | E27: per gelas | F27: ✅ Ada | G27: Pesan H-1 | H27: 1 hari
B30: 📌 CATATAN: Harga dapat berubah sewaktu-waktu. Hubungi kami untuk konfirmasi harga terbaru.

Sheet 🧮 Kalkulator Harga
B1: 🧮 KALKULATOR HARGA JUAL YANG TEPAT
B2: 💡 Masukkan biaya bahan dan target keuntungan — harga jual otomatis terhitung!
B4: 🟡 Isi kolom kuning saja — hasil di kolom hijau otomatis!
B6: 📌 NAMA MENU:
B7: Nama Menu yang Dihitung: | C7: Nasi Box Ayam Bakar
B9: A. BIAYA BAHAN (per porsi/pcs)
B10: Bahan Utama (ayam, tepung, dll) | C10: 10000
B11: Bumbu & Rempah | C11: 3000
B12: Minyak / Mentega | C12: 1500
B13: Kemasan (kotak, plastik, dll) | C13: 2000
B14: Bahan Pelengkap (sayur, kerupuk, dll) | C14: 2000
B15: Lain-lain | C15: 0
B16: 📌 TOTAL BIAYA BAHAN | C16: =SUM(C10:C15) -> 18500
B18: B. BIAYA OPERASIONAL (per porsi/pcs)
B19: Gas / Listrik (dibagi jumlah porsi) | C19: 500
B20: Ongkos kirim (jika ada) | C20: 0
B21: Upah tenaga bantu (jika ada) | C21: 1000
B22: 📌 TOTAL BIAYA OPERASIONAL | C22: =SUM(C19:C21) -> 1500
B24: 🔴 TOTAL HPP (Harga Pokok per Porsi) | C24: =C16+C22 -> 20000
B26: C. TARGET KEUNTUNGAN
B27: Target Keuntungan (%) | C27: 0.35 | D27: ← Ganti angkanya (contoh: 35% = 0.35)
B29: 🎉 HASIL KALKULASI HARGA JUAL
B30: 💰 Harga Jual MINIMUM (tidak rugi) | C30: =CEILING(C24*(1+C27),500) -> 27000 | D30: ← Pakai harga ini minimal
B31: 🏷️ Harga Jual DISARANKAN (+5% buffer) | C31: =CEILING(C24*(1+C27)*1.05,500) -> 28500 | D31: ← Harga ini lebih aman ✅
B32: 🎊 Keuntungan Per Porsi | C32: =C30-C24 -> 7000 | D32: ← Untung per 1 porsi
B33: 📈 Keuntungan Jika Jual 50 Porsi | C33: =C32*50 -> 350000 | D33: ← Proyeksi 50 porsi
B34: 📊 Keuntungan Jika Jual 100 Porsi | C34: =C32*100 -> 700000 | D34: ← Proyeksi 100 porsi
